{"errorMessage": "An error occurred (AccessDenied) when calling the PutObject operation: Access Denied", "errorType": "ClientError", "requestId": "4d900160-b6cc-47fd-9703-a4955104e286", "stackTrace": ["  File \"/var/task/index.py\", line 34, in handler\n    s3.put_object(\n", "  File \"/var/lang/lib/python3.12/site-packages/botocore/client.py\", line 602, in _api_call\n    return self._make_api_call(operation_name, kwargs)\n", "  File \"/var/lang/lib/python3.12/site-packages/botocore/context.py\", line 123, in wrapper\n    return func(*args, **kwargs)\n", "  File \"/var/lang/lib/python3.12/site-packages/botocore/client.py\", line 1078, in _make_api_call\n    raise error_class(parsed_response, operation_name)\n"]}